<?xml version="1.0"?>
<robot xmlns:xacro="http://www.ros.org/wiki/xacro" name="L580">

  <material name="yellow"><color rgba="1.0 0.8 0.0 1.0"/></material>
  <material name="grey"><color rgba="0.5 0.5 0.5 1.0"/></material>
  <material name="black"><color rgba="0.1 0.1 0.1 1.0"/></material>

  <link name="dummy_link"/>

  <joint name="dummy_to_base" type="fixed">
    <parent link="dummy_link"/>
    <child link="base_link"/>
    <origin xyz="0 0 2.6" rpy="0 0 0"/>
  </joint>

  <link name="base_link">
    <inertial>
      <mass value="26805.699"/>
      <origin xyz="-2.61002 0.0 -0.48814" rpy="0 0 0"/>
      <inertia ixx="27508.280" ixy="0.0" ixz="3824.267" iyy="80073.520" iyz="0.0" izz="72480.689"/>
    </inertial>
    <visual><geometry><mesh filename="file:///$(find loader_sim_pkg)/meshes/body.STL"/></geometry><material name="yellow"/></visual>
    <collision><geometry><mesh filename="file:///$(find loader_sim_pkg)/meshes/body.STL"/></geometry></collision>
  </link>

  <joint name="front_wheel_joint" type="continuous">
    <parent link="base_link"/>
    <child link="front_wheel_link"/>
    <origin xyz="0.43775 0 -1.5816" rpy="-1.57 -1.57 0"/>
    <axis xyz="0 0 1"/>
  </joint>
  <link name="front_wheel_link">
    <inertial>
      <mass value="2909.2494"/>
      <origin xyz="0 0 0" rpy="0 0 0"/>
      <inertia ixx="5578.194" ixy="0.0" ixz="0.0" iyy="5578.194" iyz="0.0" izz="1297.409"/>
    </inertial>
    <visual><geometry><mesh filename="file:///$(find loader_sim_pkg)/meshes/wheel.STL"/></geometry><material name="black"/></visual>
    <collision><geometry><mesh filename="file:///$(find loader_sim_pkg)/meshes/wheel.STL"/></geometry></collision>
  </link>

  <joint name="rear_wheel_joint" type="continuous">
    <parent link="base_link"/>
    <child link="rear_wheel_link"/>
    <origin xyz="-3.33631 0 -1.5816" rpy="-1.57 -1.57 0"/>
    <axis xyz="0 0 1"/>
  </joint>
  <link name="rear_wheel_link">
    <inertial>
      <mass value="2909.2494"/>
      <origin xyz="0 0 0" rpy="0 0 0"/>
      <inertia ixx="5578.194" ixy="0.0" ixz="0.0" iyy="5578.194" iyz="0.0" izz="1297.409"/>
    </inertial>
    <visual><geometry><mesh filename="file:///$(find loader_sim_pkg)/meshes/wheel.STL"/></geometry><material name="black"/></visual>
    <collision><geometry><mesh filename="file:///$(find loader_sim_pkg)/meshes/wheel.STL"/></geometry></collision>
  </link>

  <joint name="arm_joint2" type="revolute">
    <parent link="base_link"/>
    <child link="arm_link1"/>
    <origin xyz="-0.25834 0 0.08169" rpy="-1.57 0.40815617 0"/>
    <axis xyz="0 0 1"/>
    <limit lower="-1.5" upper="1.5" effort="100000" velocity="0.5"/>
    <dynamics damping="100.0" friction="10.0"/> </joint>
  <link name="arm_link1">
    <inertial>
      <mass value="501.9812"/>
      <origin xyz="1.28313 0.0 0.0" rpy="0 0 0"/>
      <inertia ixx="52.903" ixy="0.0" ixz="0" iyy="123.643" iyz="0.0" izz="138.050"/>
    </inertial>
    <visual><geometry><mesh filename="file:///$(find loader_sim_pkg)/meshes/arm_link1.STL"/></geometry><material name="yellow"/></visual>
    <collision><geometry><mesh filename="file:///$(find loader_sim_pkg)/meshes/arm_link1.STL"/></geometry></collision>
  </link>

  <joint name="arm_joint4" type="revolute">
    <parent link="arm_link1"/>
    <child link="bucket"/>
    <origin xyz="3.26512 0 0" rpy="0 0 -0.329692696"/>
    <axis xyz="0 0 1"/>
    <limit lower="-2.0" upper="2.0" effort="100000" velocity="0.5"/>
    <dynamics damping="50.0" friction="10.0"/> </joint>
  <link name="bucket">
    <inertial>
      <mass value="30.2912"/>
      <origin xyz="0.81076 -0.35 0.0" rpy="0 0 0"/>
      <inertia ixx="65.841" ixy="0.0" ixz="0.0" iyy="65.841" iyz="0.0" izz="8.928"/>
    </inertial>
    <visual><geometry><mesh filename="file:///$(find loader_sim_pkg)/meshes/bucket.STL"/></geometry><material name="black"/></visual>
    <collision><geometry><mesh filename="file:///$(find loader_sim_pkg)/meshes/bucket.STL"/></geometry></collision>
  </link>

  <joint name="bellcrank_joint" type="revolute">
    <parent link="arm_link1"/>
    <child link="tilt_link1"/>
    <origin xyz="1.85125 -0.53443 0" rpy="0 0 0.436681379"/>
    <axis xyz="0 0 1"/>
    <limit lower="-3.0" upper="3.0" effort="10000" velocity="1.0"/>
    <dynamics damping="10.0"/>
  </joint>

  <link name="tilt_link1">
    <inertial>
      <mass value="111.5235"/>
      <origin xyz="0.10893 0.0 0.0" rpy="0 0 0"/> <inertia ixx="3.388"  ixy="0.0"  ixz="0.0" iyy="19.830" iyz="0.0" izz="21.937"/>
    </inertial>
    <visual><geometry><mesh filename="file:///$(find loader_sim_pkg)/meshes/tilt_link1_co2.STL"/></geometry><material name="yellow"/></visual>
    <collision><geometry><mesh filename="file:///$(find loader_sim_pkg)/meshes/tilt_link1_co2.STL"/></geometry></collision>
  </link>

  <joint name="tilt_joint3" type="revolute">
    <parent link="tilt_link1"/>
    <child link="tilt_link2"/>
    <origin xyz="0.82217 0.48340 0" rpy="0 0 -1.13446401"/>
    <axis xyz="0 0 1"/>
    <limit lower="-3.0" upper="3.0" effort="10000" velocity="1.0"/>
    <dynamics damping="5.0"/>
  </joint>

  <link name="tilt_link2">
    <inertial>
      <mass value="12.3809"/>
      <origin xyz="0.45346 0.0 0.0" rpy="0 0 0"/>
      <inertia ixx="0.040" ixy="0.0" ixz="0.0" iyy="1.207" iyz="0.0" izz="1.238"/>
    </inertial>
    <visual><geometry><mesh filename="file:///$(find loader_sim_pkg)/meshes/tilt_link2.STL"/></geometry><material name="yellow"/></visual>
    <collision><geometry><mesh filename="file:///$(find loader_sim_pkg)/meshes/tilt_link2.STL"/></geometry></collision>
  </link>

  <joint name="arm_joint1" type="revolute">
    <parent link="base_link"/>
    <child link="cil_link2"/>
    <origin xyz="-0.30062 0 -0.53381" rpy="-1.57 0.08666653 0"/>
    <axis xyz="0 0 1"/>
    <limit lower="-1.0" upper="1.0" effort="10000" velocity="1.0"/>
  </joint>
  <link name="cil_link2">
    <inertial>
      <mass value="47.9208"/>
      <origin xyz="0.42516 0 0" rpy="0 0 0"/>
      <inertia ixx="0.479" ixy="0.0" ixz="0.0" iyy="5.193" iyz="0.0" izz="5.215"/>
    </inertial>
    <visual><geometry><mesh filename="file:///$(find loader_sim_pkg)/meshes/cil2.STL"/></geometry><material name="grey"/></visual>
    <collision><geometry><mesh filename="file:///$(find loader_sim_pkg)/meshes/cil2.STL"/></geometry></collision>
  </link>

  <joint name="cil2_joint" type="prismatic">
    <parent link="cil_link2"/>
    <child link="cil_pris_link2"/>
    <origin xyz="0.42917 0 0" rpy="3.14 -1.57 0"/>
    <axis xyz="0 0 1"/>
    <limit lower="0.0" upper="1.0" effort="5000000000000" velocity="0.2"/>
  </joint>
  <link name="cil_pris_link2">
    <inertial>
      <mass value="12.53999"/>
      <origin xyz="0 0 0.49872" rpy="0 0 0"/>
      <inertia ixx="1.070" ixy="0.0" ixz="0.0" iyy="1.062" iyz="0.0" izz="0.031"/>
    </inertial>
    <visual><geometry><mesh filename="file:///$(find loader_sim_pkg)/meshes/cil2_pris.STL"/></geometry><material name="grey"/></visual>
    <collision><geometry><mesh filename="file:///$(find loader_sim_pkg)/meshes/cil2_pris.STL"/></geometry></collision>
  </link>

  <joint name="tilt_joint1" type="revolute">
    <parent link="base_link"/>
    <child link="cil_link1"/>
    <origin xyz="0 0 0" rpy="-1.57 -0.24965842 0"/>
    <axis xyz="0 0 1"/>
    <limit lower="-1.0" upper="1.0" effort="10000" velocity="1.0"/>
  </joint>
  <link name="cil_link1">
    <inertial>
      <mass value="47.9208"/>
      <origin xyz="0.42516 0 0" rpy="0 0 0"/>
      <inertia ixx="0.479" ixy="0.0" ixz="0.0" iyy="5.193" iyz="0.0" izz="5.215"/>
    </inertial>
    <visual><geometry><mesh filename="file:///$(find loader_sim_pkg)/meshes/cil1.STL"/></geometry><material name="grey"/></visual>
    <collision><geometry><mesh filename="file:///$(find loader_sim_pkg)/meshes/cil1.STL"/></geometry></collision>
  </link>

  <joint name="cil1_joint" type="prismatic">
    <parent link="cil_link1"/>
    <child link="cil_pris_link1"/>
    <origin xyz="0.37347 0 0" rpy="3.14 -1.57 0"/>
    <axis xyz="0 0 1"/>
    <limit lower="0.0" upper="0.7" effort="5000000000000" velocity="0.2"/>
  </joint>
  <link name="cil_pris_link1">
    <inertial>
      <mass value="12.53999"/>
      <origin xyz="0 0 0.49872" rpy="0 0 0"/>
      <inertia ixx="1.070" ixy="0.0" ixz="0.0" iyy="1.062" iyz="0.0" izz="0.031"/>
    </inertial>
    <visual><geometry><mesh filename="file:///$(find loader_sim_pkg)/meshes/cil1_pris.STL"/></geometry><material name="grey"/></visual>
    <collision><geometry><mesh filename="file:///$(find loader_sim_pkg)/meshes/cil1_pris.STL"/></geometry></collision>
  </link>

  <gazebo>
    <joint name="lift_loop_joint" type="revolute">
      <parent>cil_pris_link2</parent>
      <child>arm_link1</child>
      <pose>0 0 1.33635 3.14 -1.57 0</pose> 
      <axis><xyz>0 0 1</xyz></axis>
    </joint>

    <joint name="tilt_piston_loop" type="revolute">
      <parent>cil_pris_link1</parent>
      <child>tilt_link1</child>
      <pose>0.89626 0 0 3.14 -1.57 0</pose> 
      <axis><xyz>0 0 1</xyz></axis>
    </joint>

    <joint name="dogbone_bucket_loop" type="revolute">
      <parent>tilt_link2</parent>
      <child>bucket</child>
      <pose>0.92750 0 0 0 0 0.368089939</pose> 
      <axis><xyz>0 0 1</xyz></axis>
    </joint>
  </gazebo>

  <ros2_control name="GazeboSystem" type="system">
    <hardware>
        <plugin>gazebo_ros2_control/GazeboSystem</plugin>
    </hardware>

    <joint name="front_wheel_joint">
        <command_interface name="velocity"/>
        <state_interface name="position">
            <param name="initial_value">0.0</param>
        </state_interface>
        <state_interface name="velocity"/>
    </joint>
    <joint name="rear_wheel_joint">
        <command_interface name="velocity"/>
        <state_interface name="position">
            <param name="initial_value">0.0</param>
        </state_interface>
        <state_interface name="velocity"/>
    </joint>

    <joint name="cil1_joint">
        <command_interface name="velocity"/>
        <state_interface name="position">
            <param name="initial_value">0.0</param>
        </state_interface>
        <state_interface name="velocity"/>
    </joint>
    <joint name="cil2_joint">
        <command_interface name="velocity"/>
        <state_interface name="position">
            <param name="initial_value">0.0</param>
        </state_interface>
        <state_interface name="velocity"/>
    </joint>
  </ros2_control>

  <gazebo>
    <plugin filename="libgazebo_ros2_control.so" name="gazebo_ros2_control">
        <robot_sim_type>gazebo_ros2_control/GazeboSystem</robot_sim_type>
        <parameters>$(find loader_sim_pkg)/config/controllers.yaml</parameters>
    </plugin>
  </gazebo>

  <gazebo reference="front_wheel_link">
      <surface>
        <friction>
          <ode>
            <slip1>0.0</slip1>
            <slip2>0.0</slip2>
            <mu>1.2</mu>
            <mu2>1.2</mu2>
          </ode>
        </friction>
      </surface>
      <material>Gazebo/Grey</material>
  </gazebo>

  <gazebo reference="rear_wheel_link">
      <surface>
        <friction>
          <ode>
            <slip1>0.0</slip1>
            <slip2>0.0</slip2>
            <mu>1.2</mu>
            <mu2>1.2</mu2>
          </ode>
        </friction>
      </surface>
      <material>Gazebo/Grey</material>
  </gazebo>

</robot>